<?xml version="1.0" encoding="utf-8"?>
<!-- =================================================================================== -->
<!-- |    This document was autogenerated by xacro from abb_irb4600_60_205.xacro       | -->
<!-- |    EDITING THIS FILE BY HAND IS NOT RECOMMENDED                                 | -->
<!-- =================================================================================== -->
<robot name="abb_irb">
  <!--Tento file sa pouziva-->
  <gazebo>
    <plugin filename="libgazebo_ros_control.so" name="gazebo_ros_control">
      <robotNamespace>/abb_irb</robotNamespace>
    </plugin>
  </gazebo>
  <!-- Link1 -->
  <gazebo reference="base_link">
    <material>Gazebo/Orange</material>
  </gazebo>
  <gazebo reference="link_1">
    <material>Gazebo/Orange</material>
  </gazebo>
  <gazebo reference="link_2">
    <material>Gazebo/Orange</material>
  </gazebo>
  <gazebo reference="link_3">
    <material>Gazebo/Orange</material>
  </gazebo>
  <gazebo reference="link_4">
    <material>Gazebo/Orange</material>
  </gazebo>
  <gazebo reference="link_5">
    <material>Gazebo/Orange</material>
  </gazebo>
  <gazebo reference="link_6">
    <material>Gazebo/Orange</material>
  </gazebo>
  <gazebo reference="tool0">
    <material>Gazebo/Orange</material>
  </gazebo>
  <gazebo reference="kinect_mesh">
    <material>Gazebo/Black</material>
  </gazebo>
  <!-- link list -->
  <link name="world"/>
  <joint name="to_world" type="fixed">
    <origin rpy="0 0 0" xyz="0 0 0"/>
    <parent link="world"/>
    <child link="base_link"/>
  </joint>
  <link name="base_link">
    <visual>
      <origin rpy="0 0 0" xyz="0 0 0"/>
      <geometry>
        <mesh filename="package://abb_model/meshes/abb_irb4600_60_205/visual/base_link.stl"/>
      </geometry>
      <material name="abb_white">
        <color rgba="0.8 0.8 0.8 1"/>
      </material>
    </visual>
    <collision>
      <origin rpy="0 0 0" xyz="0 0 0"/>
      <geometry>
        <mesh filename="package://abb_model/meshes/abb_irb4600_60_205/collision/base_link.stl"/>
      </geometry>
      <material name="yellow">
        <color rgba="0 1 1 1"/>
      </material>
    </collision>
    <inertial>
      <origin rpy="0 0 0" xyz="0 0 0"/>
      <mass value="1"/>
      <inertia ixx="0.01" ixy="0.01" ixz="0.01" iyy="0.01" iyz="0.01" izz="0.01"/>
    </inertial>
  </link>
  <link name="link_1">
    <visual>
      <origin rpy="0 0 0" xyz="0 0 0"/>
      <geometry>
        <mesh filename="package://abb_model/meshes/abb_irb4600_60_205/visual/link_1.stl"/>
      </geometry>
      <material name="abb_white"/>
    </visual>
    <collision>
      <origin rpy="0 0 0" xyz="0 0 0"/>
      <geometry>
        <mesh filename="package://abb_model/meshes/abb_irb4600_60_205/collision/link_1.stl"/>
      </geometry>
      <material name="yellow"/>
    </collision>
    <inertial>
      <origin rpy="0 0 0" xyz="0 0 0"/>
      <mass value="1"/>
      <inertia ixx="0.01" ixy="0.01" ixz="0.01" iyy="0.01" iyz="0.01" izz="0.01"/>
    </inertial>
  </link>
  <link name="link_2">
    <visual>
      <origin rpy="0 0 0" xyz="0 0 0"/>
      <geometry>
        <mesh filename="package://abb_model/meshes/abb_irb4600_60_205/visual/link_2.stl"/>
      </geometry>
      <material name="abb_white"/>
    </visual>
    <collision>
      <origin rpy="0 0 0" xyz="0 0 0"/>
      <geometry>
        <mesh filename="package://abb_model/meshes/abb_irb4600_60_205/collision/link_2.stl"/>
      </geometry>
      <material name="yellow"/>
    </collision>
    <inertial>
      <origin rpy="0 0 0" xyz="0 0 0"/>
      <mass value="1"/>
      <inertia ixx="0.01" ixy="0.01" ixz="0.01" iyy="0.01" iyz="0.01" izz="0.01"/>
    </inertial>
  </link>
  <link name="link_3">
    <visual>
      <origin rpy="0 0 0" xyz="0 0 0"/>
      <geometry>
        <mesh filename="package://abb_model/meshes/abb_irb4600_60_205/visual/link_3.stl"/>
      </geometry>
      <material name="abb_white"/>
    </visual>
    <collision>
      <origin rpy="0 0 0" xyz="0 0 0"/>
      <geometry>
        <mesh filename="package://abb_model/meshes/abb_irb4600_60_205/collision/link_3.stl"/>
      </geometry>
      <material name="yellow"/>
    </collision>
    <inertial>
      <origin rpy="0 0 0" xyz="0 0 0"/>
      <mass value="1"/>
      <inertia ixx="0.01" ixy="0.01" ixz="0.01" iyy="0.01" iyz="0.01" izz="0.01"/>
    </inertial>
  </link>
  <link name="link_4">
    <visual>
      <origin rpy="0 0 0" xyz="0 0 0"/>
      <geometry>
        <mesh filename="package://abb_model/meshes/abb_irb4600_60_205/visual/link_4.stl"/>
      </geometry>
      <material name="abb_white"/>
    </visual>
    <collision>
      <origin rpy="0 0 0" xyz="0 0 0"/>
      <geometry>
        <mesh filename="package://abb_model/meshes/abb_irb4600_60_205/collision/link_4.stl"/>
      </geometry>
      <material name="yellow"/>
    </collision>
    <inertial>
      <origin rpy="0 0 0" xyz="0 0 0"/>
      <mass value="1"/>
      <inertia ixx="0.01" ixy="0.01" ixz="0.01" iyy="0.01" iyz="0.01" izz="0.01"/>
    </inertial>
  </link>
  <link name="link_5">
    <visual>
      <origin rpy="0 0 0" xyz="0 0 0"/>
      <geometry>
        <mesh filename="package://abb_model/meshes/abb_irb4600_60_205/visual/link_5.stl"/>
      </geometry>
      <material name="abb_white"/>
    </visual>
    <collision>
      <origin rpy="0 0 0" xyz="0 0 0"/>
      <geometry>
        <mesh filename="package://abb_model/meshes/abb_irb4600_60_205/collision/link_5.stl"/>
      </geometry>
      <material name="yellow"/>
    </collision>
    <inertial>
      <origin rpy="0 0 0" xyz="0 0 0"/>
      <mass value="1"/>
      <inertia ixx="0.01" ixy="0.01" ixz="0.01" iyy="0.01" iyz="0.01" izz="0.01"/>
    </inertial>
  </link>
  <link name="link_6">
    <visual>
      <origin rpy="0 0 0" xyz="0 0 0"/>
      <geometry>
        <mesh filename="package://abb_model/meshes/abb_irb4600_60_205/visual/link_6.stl"/>
      </geometry>
      <material name="abb_grey">
        <color rgba="0.2 0.2 0.2 1"/>
      </material>
    </visual>
    <collision>
      <origin rpy="0 0 0" xyz="0 0 0"/>
      <geometry>
        <mesh filename="package://abb_model/meshes/abb_irb4600_60_205/collision/link_6.stl"/>
      </geometry>
      <material name="yellow"/>
    </collision>
    <inertial>
      <origin rpy="0 0 0" xyz="0 0 0"/>
      <mass value="1"/>
      <inertia ixx="0.01" ixy="0.01" ixz="0.01" iyy="0.01" iyz="0.01" izz="0.01"/>
    </inertial>
  </link>
  <link name="tool0"/>
  <!-- end of link list -->
  <!-- TODO ALL JOINT LIMITS limits are edited and reduced to lower values-->
  <!-- joint list -->
  <joint name="joint_1" type="revolute">
    <origin rpy="1.10409999285604E-14 0 0" xyz="0 0 0.1535"/>
    <parent link="base_link"/>
    <child link="link_1"/>
    <axis xyz="0 0 1"/>
    <limit effort="1000" lower="-2.62" upper="2.62" velocity="3.05"/>
  </joint>
  <joint name="joint_2" type="revolute">
    <origin rpy="-1.57772181044202E-30 0 0" xyz="0.174999999999998 -0.0515489073390827 0.341500000000001"/>
    <parent link="link_1"/>
    <child link="link_2"/>
    <axis xyz="0 1 0"/>
    <limit effort="1000" lower="-1.57" upper="1.57" velocity="3.05"/>
  </joint>
  <joint name="joint_3" type="revolute">
    <origin rpy="-1.11022302462516E-14 0 0" xyz="0 0 0.9"/>
    <parent link="link_2"/>
    <child link="link_3"/>
    <axis xyz="0 1 0"/>
    <limit effort="1000" lower="-3.14" upper="1.31" velocity="4.36"/>
  </joint>
  <joint name="joint_4" type="revolute">
    <origin rpy="0 0 0" xyz="0.331499999999985 0.0515489073390958 0.175000000000008"/>
    <parent link="link_3"/>
    <child link="link_4"/>
    <axis xyz="1 0 0"/>
    <limit effort="1000" lower="-6.98" upper="6.98" velocity="4.36"/>
  </joint>
  <joint name="joint_5" type="revolute">
    <origin rpy="0 0 0" xyz="0.628499999999995 0 0"/>
    <parent link="link_4"/>
    <child link="link_5"/>
    <axis xyz="0 1 0"/>
    <limit effort="1000" lower="-2.09" upper="2.18" velocity="4.36"/>
  </joint>
  <joint name="joint_6" type="revolute">
    <origin rpy="0 0 0" xyz="0 0 0"/>
    <parent link="link_5"/>
    <child link="link_6"/>
    <axis xyz="1 0 0"/>
    <limit effort="1000" lower="-6.98" upper="6.98" velocity="6.28"/>
  </joint>
  <joint name="joint_6-tool0" type="fixed">
    <parent link="link_6"/>
    <child link="tool0"/>
    <origin rpy="0 1.570796 0" xyz="0.135 0 0"/>
  </joint>
  <transmission name="tran1">
    <type>transmission_interface/SimpleTransmission</type>
    <joint name="joint_1">
      <hardwareInterface>PositionJointInterface</hardwareInterface>
    </joint>
    <actuator name="motor_1">
      <hardwareInterface>PositionJointInterface</hardwareInterface>
      <mechanicalReduction>1000</mechanicalReduction>
    </actuator>
  </transmission>
  <transmission name="tran2">
    <type>transmission_interface/SimpleTransmission</type>
    <joint name="joint_2">
      <hardwareInterface>PositionJointInterface</hardwareInterface>
    </joint>
    <actuator name="motor_2">
      <hardwareInterface>PositionJointInterface</hardwareInterface>
      <mechanicalReduction>1000</mechanicalReduction>
    </actuator>
  </transmission>
  <transmission name="tran3">
    <type>transmission_interface/SimpleTransmission</type>
    <joint name="joint_3">
      <hardwareInterface>PositionJointInterface</hardwareInterface>
    </joint>
    <actuator name="motor_3">
      <hardwareInterface>PositionJointInterface</hardwareInterface>
      <mechanicalReduction>1000</mechanicalReduction>
    </actuator>
  </transmission>
  <transmission name="tran4">
    <type>transmission_interface/SimpleTransmission</type>
    <joint name="joint_4">
      <hardwareInterface>PositionJointInterface</hardwareInterface>
    </joint>
    <actuator name="motor_4">
      <hardwareInterface>PositionJointInterface</hardwareInterface>
      <mechanicalReduction>1000</mechanicalReduction>
    </actuator>
  </transmission>
  <transmission name="tran5">
    <type>transmission_interface/SimpleTransmission</type>
    <joint name="joint_5">
      <hardwareInterface>PositionJointInterface</hardwareInterface>
    </joint>
    <actuator name="motor_5">
      <hardwareInterface>PositionJointInterface</hardwareInterface>
      <mechanicalReduction>1000</mechanicalReduction>
    </actuator>
  </transmission>
  <transmission name="tran6">
    <type>transmission_interface/SimpleTransmission</type>
    <joint name="joint_6">
      <hardwareInterface>PositionJointInterface</hardwareInterface>
    </joint>
    <actuator name="motor_6">
      <hardwareInterface>PositionJointInterface</hardwareInterface>
      <mechanicalReduction>1000</mechanicalReduction>
    </actuator>
  </transmission>
  <gazebo reference="tool0">
    <material>Gazebo/Black</material>
    <sensor name="kinect" type="depth">
      <update_rate>10.0</update_rate>
      <camera name="depth_cam">
        <horizontal_fov>1</horizontal_fov>
        <image>
          <width>640</width>
          <height>480</height>
          <format>R8G8B8</format>
        </image>
        <clip>
          <near>0.05</near>
          <far>5</far>
        </clip>
      </camera>
      <plugin filename="libgazebo_ros_openni_kinect.so" name="kinect_controller">
        <baseline>0.2</baseline>
        <alwaysOn>true</alwaysOn>
        <updateRate>10.0</updateRate>
        <cameraName>kinect</cameraName>
        <imageTopicName>/kinect/rgb/image_raw</imageTopicName>
        <cameraInfoTopicName>/kinect/depth/camera_info</cameraInfoTopicName>
        <depthImageTopicName>/kinect/depth/image_raw</depthImageTopicName>
        <depthImageInfoTopicName>/kinect/depth/depth_camera_info</depthImageInfoTopicName>
        <pointCloudTopicName>/kinect/depth/points</pointCloudTopicName>
        <frameName>link_depthtf</frameName>
        <pointCloudCutoff>0.4</pointCloudCutoff>
        <pointCloudCutoffMax>8.0</pointCloudCutoffMax>
        <distortionK1>0.00000001</distortionK1>
        <distortionK2>0.00000001</distortionK2>
        <distortionK3>0.00000001</distortionK3>
        <distortionT1>0.00000001</distortionT1>
        <distortionT2>0.00000001</distortionT2>
        <CxPrime>0</CxPrime>
        <Cx>0</Cx>
        <Cy>0</Cy>
        <focalLength>0</focalLength>
        <hackBaseline>0</hackBaseline>
      </plugin>
    </sensor>
  </gazebo>
  <link name="link_depthtf"/>
  <link name="kinect_mesh">
    <visual>
      <origin rpy="0 0 1.57" xyz="0 0 0"/>
      <geometry>
        <mesh filename="package://abb_model/meshes/kinect/visual/kinect_sensor.stl" scale="0.001 0.001 0.001"/>
      </geometry>
      <material name="abb_grey">
        <color rgba="0.2 0.2 0.2 1"/>
      </material>
    </visual>
    <collision>
      <origin rpy="0 0 1.57" xyz="0 0 0"/>
      <geometry>
        <mesh filename="package://abb_model/meshes/kinect/collision/kinect_sensor.stl" scale="0.001 0.001 0.001"/>
      </geometry>
      <material name="yellow"/>
    </collision>
    <inertial>
      <mass value="1.0"/>
      <origin rpy="0 0 0" xyz="0 0 0"/>
      <inertia ixx="0.1" ixy="0.01" ixz="0.01" iyy="0.1" iyz="0.01" izz="0.1"/>
    </inertial>
  </link>
  <joint name="to_kinect_mesh" type="fixed">
    <parent link="tool0"/>
    <child link="kinect_mesh"/>
    <origin rpy="0 0 0" xyz="0 0 0.015"/>
  </joint>
  <joint name="to_link_depthtf" type="fixed">
    <parent link="tool0"/>
    <child link="link_depthtf"/>
    <!--origin xyz="0 0 0.015" rpy="0 0 0"/-->
    <origin rpy="-1.57 0 -1.57" xyz="0 0 0"/>
  </joint>
</robot>
