<?xml version="1.0" ?>
<!-- =================================================================================== -->
<!-- |    This document was autogenerated by xacro from /home/andrejvysny/catkin_ws/src/abb_irb4600_support/urdf/irb4600_60_205.xacro | -->
<!-- |    EDITING THIS FILE BY HAND IS NOT RECOMMENDED                                 | -->
<!-- =================================================================================== -->
<robot name="abb_irb4600_60_205">
    <!-- link list -->
    <link name="base_link">
        <collision name="collision">
            <geometry>
                <mesh filename="package://abb_irb4600_support/meshes/irb4600/collision/base_link.stl" />
            </geometry>
        </collision>
        <visual name="visual">
            <geometry>
                <mesh filename="package://abb_irb4600_support/meshes/irb4600/visual/base_link.dae" />
            </geometry>
            <material name="yellow">
                <color rgba="1 1 0 1" />
            </material>
        </visual>
        <inertial>
            <mass value="0.1" />
            <origin xyz="0 0 0" rpy="0 0 0" />
            <inertia ixx="0.03" iyy="0.03" izz="0.03" ixy="0.0" ixz="0.0" iyz="0.0" />
        </inertial>
    </link>
    <link name="link_1">
        <collision name="collision">
            <geometry>
                <mesh filename="package://abb_irb4600_support/meshes/irb4600/collision/link_1.stl" />
            </geometry>
        </collision>
        <visual name="visual">
            <geometry>
                <mesh filename="package://abb_irb4600_support/meshes/irb4600/visual/link_1.dae" />
            </geometry>
            <material name="yellow" />
        </visual>
        <inertial>
            <mass value="0.1" />
            <origin xyz="0 0 0" rpy="0 0 0" />
            <inertia ixx="0.03" iyy="0.03" izz="0.03" ixy="0.0" ixz="0.0" iyz="0.0" />
        </inertial>
    </link>
    <link name="link_2">
        <collision name="collision">
            <geometry>
                <mesh filename="package://abb_irb4600_support/meshes/irb4600_60_205/collision/link_2.stl" />
            </geometry>
        </collision>
        <visual name="visual">
            <geometry>
                <mesh filename="package://abb_irb4600_support/meshes/irb4600_60_205/visual/link_2.dae" />
            </geometry>
            <material name="yellow" />
        </visual>
        <inertial>
            <mass value="0.1" />
            <origin xyz="0 0 0" rpy="0 0 0" />
            <inertia ixx="0.03" iyy="0.03" izz="0.03" ixy="0.0" ixz="0.0" iyz="0.0" />
        </inertial>
    </link>
    <link name="link_3">
        <collision name="collision">
            <geometry>
                <mesh filename="package://abb_irb4600_support/meshes/irb4600_60_205/collision/link_3.stl" />
            </geometry>
        </collision>
        <visual name="visual">
            <geometry>
                <mesh filename="package://abb_irb4600_support/meshes/irb4600_60_205/visual/link_3.dae" />
            </geometry>
            <material name="yellow" />
        </visual>
        <inertial>
            <mass value="0.1" />
            <origin xyz="0 0 0" rpy="0 0 0" />
            <inertia ixx="0.03" iyy="0.03" izz="0.03" ixy="0.0" ixz="0.0" iyz="0.0" />
        </inertial>
    </link>
    <link name="link_4">
        <collision name="collision">
            <geometry>
                <mesh filename="package://abb_irb4600_support/meshes/irb4600_60_205/collision/link_4.stl" />
            </geometry>
        </collision>
        <visual name="visual">
            <geometry>
                <mesh filename="package://abb_irb4600_support/meshes/irb4600_60_205/visual/link_4.dae" />
            </geometry>
            <material name="yellow" />
        </visual>
        <inertial>
            <mass value="0.1" />
            <origin xyz="0 0 0" rpy="0 0 0" />
            <inertia ixx="0.03" iyy="0.03" izz="0.03" ixy="0.0" ixz="0.0" iyz="0.0" />
        </inertial>
    </link>
    <link name="link_5">
        <collision name="collision">
            <geometry>
                <mesh filename="package://abb_irb4600_support/meshes/irb4600_60_205/collision/link_5.stl" />
            </geometry>
        </collision>
        <visual name="visual">
            <geometry>
                <mesh filename="package://abb_irb4600_support/meshes/irb4600_60_205/visual/link_5.dae" />
            </geometry>
            <material name="yellow" />
        </visual>
        <inertial>
            <mass value="0.1" />
            <origin xyz="0 0 0" rpy="0 0 0" />
            <inertia ixx="0.03" iyy="0.03" izz="0.03" ixy="0.0" ixz="0.0" iyz="0.0" />
        </inertial>
    </link>
    <link name="link_6">
        <collision name="collision">
            <geometry>
                <mesh filename="package://abb_irb4600_support/meshes/irb4600_60_205/collision/link_6.stl" />
            </geometry>
        </collision>
        <visual name="visual">
            <geometry>
                <mesh filename="package://abb_irb4600_support/meshes/irb4600_60_205/visual/link_6.dae" />
            </geometry>
            <material name="yellow" />
        </visual>
        <inertial>
            <mass value="0.1" />
            <origin xyz="0 0 0" rpy="0 0 0" />
            <inertia ixx="0.03" iyy="0.03" izz="0.03" ixy="0.0" ixz="0.0" iyz="0.0" />
        </inertial>
    </link>
    <!-- end of link list -->
    <!-- joint list -->
    <joint name="joint_1" type="revolute">
        <origin rpy="0 0 0" xyz="0 0 0.495" />
        <axis xyz="0 0 1" />
        <parent link="base_link" />
        <child link="link_1" />
        <limit effort="0" lower="-3.141" upper="3.141" velocity="3.054" />
    </joint>
    <joint name="joint_2" type="revolute">
        <origin rpy="0 0 0" xyz="0.175 0 0" />
        <axis xyz="0 1 0" />
        <parent link="link_1" />
        <child link="link_2" />
        <limit effort="0" lower="-1.570" upper="2.617" velocity="3.054" />
    </joint>
    <joint name="joint_3" type="revolute">
        <origin rpy="0 0 0" xyz="0 0 0.9" />
        <axis xyz="0 1 0" />
        <parent link="link_2" />
        <child link="link_3" />
        <limit effort="0" lower="-3.141" upper="1.308" velocity="3.054" />
    </joint>
    <joint name="joint_4" type="revolute">
        <origin rpy="0 0 0" xyz="0 0 0.175" />
        <axis xyz="1 0 0" />
        <parent link="link_3" />
        <child link="link_4" />
        <limit effort="0" lower="-6.981" upper="6.981" velocity="4.363" />
    </joint>
    <joint name="joint_5" type="revolute">
        <origin rpy="0 0 0" xyz="0.960 0 0 " />
        <axis xyz="0 1 0" />
        <parent link="link_4" />
        <child link="link_5" />
        <limit effort="0" lower="-2.181" upper="2.094" velocity="4.363" />
    </joint>
    <joint name="joint_6" type="revolute">
        <origin rpy="0 0 0" xyz="0.135 0 0 " />
        <axis xyz="1 0 0" />
        <parent link="link_5" />
        <child link="link_6" />
        <limit effort="0" lower="-6.981" upper="6.981" velocity="6.283" />
    </joint>
    <!-- end of joint list -->
    <!-- ROS-Industrial 'base' frame: base_link to ABB World Coordinates transform -->
    <link name="base" />
    <joint name="base_link-base" type="fixed">
        <origin rpy="0 0 0" xyz="0 0 0" />
        <parent link="base_link" />
        <child link="base" />
    </joint>
    <!-- ROS-Industrial 'flange' frame: attachment point for EEF models -->
    <link name="flange" />
    <joint name="joint_6-flange" type="fixed">
        <origin rpy="0 0 0" xyz="0 0 0" />
        <parent link="link_6" />
        <child link="flange" />
    </joint>
    <link name="-toolbase">
        <visual>
            <geometry>
                <box size=" 0.1 0.02 0.02" />
            </geometry>
            <material name="blue">
                <color rgba="0 0 1 1" />
            </material>
            <origin rpy="0 0 0" xyz="0.05 0 0" />
        </visual>
    </link>
    <joint name="joint_toolbase" type="fixed">
        <origin rpy="0 0 0" xyz="0 0 0" />
        <parent link="flange" />
        <child link="-toolbase" />
    </joint>
    <link name="-toolend">
        <visual>
            <geometry>
                <box size=" 0.02 0.02 0.02" />
            </geometry>
            <material name="green">
                <color rgba="0 1 0 1" />
            </material>
            <origin rpy="0 0 0" xyz="0.1 0 0" />
        </visual>
    </link>
    <joint name="joint_toolend" type="fixed">
        <origin rpy="0 0 0" xyz="0 0 0" />
        <parent link="-toolbase" />
        <child link="-toolend" />
    </joint>
    <!-- ROS-Industrial 'tool0' frame: all-zeros tool frame -->
    <link name="tool0" />
    <joint name="link_6-tool0" type="fixed">
        <origin rpy="0 1.5707963267948966 0" xyz="0 0 0" />
        <parent link="-toolend" />
        <child link="tool0" />
    </joint>
    <transmission name="trans_joint_1">
        <type>transmission_interface/SimpleTransmission</type>
        <joint name="joint_1">
            <hardwareInterface>hardware_interface/EffortJointInterface</hardwareInterface>
        </joint>
        <actuator name="joint_1_motor">
            <hardwareInterface>hardware_interface/EffortJointInterface</hardwareInterface>
            <mechanicalReduction>1</mechanicalReduction>
        </actuator>
    </transmission>
    <transmission name="trans_joint_2">
        <type>transmission_interface/SimpleTransmission</type>
        <joint name="joint_2">
            <hardwareInterface>hardware_interface/EffortJointInterface</hardwareInterface>
        </joint>
        <actuator name="joint_2_motor">
            <hardwareInterface>hardware_interface/EffortJointInterface</hardwareInterface>
            <mechanicalReduction>1</mechanicalReduction>
        </actuator>
    </transmission>
    <transmission name="trans_joint_3">
        <type>transmission_interface/SimpleTransmission</type>
        <joint name="joint_3">
            <hardwareInterface>hardware_interface/EffortJointInterface</hardwareInterface>
        </joint>
        <actuator name="joint_3_motor">
            <hardwareInterface>hardware_interface/EffortJointInterface</hardwareInterface>
            <mechanicalReduction>1</mechanicalReduction>
        </actuator>
    </transmission>
    <transmission name="trans_joint_4">
        <type>transmission_interface/SimpleTransmission</type>
        <joint name="joint_4">
            <hardwareInterface>hardware_interface/EffortJointInterface</hardwareInterface>
        </joint>
        <actuator name="joint_4_motor">
            <hardwareInterface>hardware_interface/EffortJointInterface</hardwareInterface>
            <mechanicalReduction>1</mechanicalReduction>
        </actuator>
    </transmission>
    <transmission name="trans_joint_5">
        <type>transmission_interface/SimpleTransmission</type>
        <joint name="joint_5">
            <hardwareInterface>hardware_interface/EffortJointInterface</hardwareInterface>
        </joint>
        <actuator name="joint_5_motor">
            <hardwareInterface>hardware_interface/EffortJointInterface</hardwareInterface>
            <mechanicalReduction>1</mechanicalReduction>
        </actuator>
    </transmission>
    <transmission name="trans_joint_6">
        <type>transmission_interface/SimpleTransmission</type>
        <joint name="joint_6">
            <hardwareInterface>hardware_interface/EffortJointInterface</hardwareInterface>
        </joint>
        <actuator name="joint_6_motor">
            <hardwareInterface>hardware_interface/EffortJointInterface</hardwareInterface>
            <mechanicalReduction>1</mechanicalReduction>
        </actuator>
    </transmission>
    <gazebo>
        <plugin name="gazebo_ros_control">
            <robotNamespace>/</robotNamespace>
        </plugin>
    </gazebo>
</robot>

