<?xml version="1.0"?>
<robot name="arm">

  <!--Links-->
  <link name="base_link">
    <visual>
      <geometry>
        <cylinder length="0.01" radius="0.05"/>
      </geometry>
      <material name="white">
        <color rgba="1 1 1 1"/>
      </material>
    </visual>
  </link>

  <link name="link_1">
    <visual>
      <geometry>
       <sphere radius="0.03"/>
      </geometry>
      <material name="gray">
        <color rgba="0.2 0.2 0.2 1"/>
      </material>
        <origin xyz="0 0 0" rpy = "0 0 0"/>
    </visual>
  </link>

  <link name="link_2">
     <visual>
      <geometry>
        <cylinder length="0.178" radius = "0.01"/>
      </geometry>
      <material name="white">
        <color rgba="1 1 1 1"/>
      </material>
      <origin xyz="0 0 0.1" rpy = "0 0 0"/>
    </visual>
  </link>

    <link name="link_2_3">
      <visual>
        <geometry>
         <sphere radius="0.03"/>
        </geometry>
        <material name="gray">
          <color rgba="0.2 0.2 0.2 1"/>
        </material>
          <origin xyz="0 0 0" rpy = "0 0 0"/>
      </visual>
    </link>
  
  <link name="link_3">
    <visual>
      <geometry>
        <cylinder length="0.203" radius = "0.01"/>
      </geometry>
      <material name="white">
        <color rgba="1 1 1 1"/>
      </material>
      <origin xyz="0 0 0.1" rpy = "0 0 0"/>
    </visual>
  </link>

 <link name="tool0"/>

  <!--Joints-->
  <joint name="joint_1" type="revolute">
    <axis xyz="0 0 1"/>
    <parent link="base_link"/>
    <child link="link_1"/>
    <origin xyz="0 0 0" rpy = "0 0 0"/>
    <limit effort="1000.0" lower="-1.62" upper="1.62" velocity="0.5"/>
  </joint>
  
  <joint name="joint_2" type="revolute">
    <axis xyz="0 1 0"/>
    <parent link="link_1"/>
    <child link="link_2"/>
    <origin xyz="0 0 0" rpy = "0 0 0"/>
    <limit effort="1000.0" lower="-0.96" upper="2.182" velocity="0.5"/>
  </joint>

    <joint name="joint_3" type="revolute">
      <axis xyz="0 1 0"/>
      <parent link="link_2"/>
      <child link="link_3"/>
      <origin xyz="0 0 0.203" rpy = "0 0 0"/>
      <limit effort="1000.0" lower="-0.96" upper="2.182" velocity="0.5"/>
    </joint>

    <joint name="joint_3-tool0" type="fixed">
      <parent link="link_3"/>
      <child link="tool0"/>
      <origin xyz="0 0 0.203" rpy = "0 0 0"/>
    </joint>

    <joint name="joint_2_3" type="fixed">
      <parent link="link_2"/>
      <child link="link_2_3"/>
      <origin xyz="0 0 0.203" rpy = "0 0 0"/>
    </joint>


</robot>
